<?xml version="1.0"?>
<robot xmlns:xacro="http://www.ros.org/wiki/xacro">

     <xacro:include filename="inertial_macros.xacro" />

<material name="white">
    <color rgba="1 1 1 1"/>
</material>

<material name="orange">
    <color rgba="1 0.3 0.1 1"/>
</material>

<material name="blue">
    <color rgba="0.2 0.2 1 1"/>
</material>

<material name="black">
    <color rgba="0 0 0 1"/>
</material>

<link name="base_link">
</link>

    <!-- CHASSIS -->

<joint name="chassis_joint" type="fixed">
    <parent link="base_link"/>
    <child link="chassis"/>
    <origin xyz="-0.1 0 0"/>
</joint>

<link name="chassis">
    <visual>
        <origin xyz="0.2 0 0.050" rpy="0 0 0"/>
        <geometry>
            <box size=".8 0.7 0.2"/>
        </geometry>
        <material name="white"/>
    </visual>
     <collision>
        <origin xyz="0.2 0 0.050" rpy="0 0 0"/>
        <geometry>
            <box size=".8 0.7 0.2"/>
        </geometry>
    </collision>

    <xacro:inertial_box mass="0.1" x="0.3" y="0.3" z="0.15">
        <origin xyz="0.2 0 0.050" rpy="0 0 0"/>
    </xacro:inertial_box>
</link>


    <!-- LEFT WHEEL -->

<joint name="left_wheel_joint" type="continuous">
    <parent link="base_link"/>
    <child link="left_wheel"/>
    <origin xyz="-0.25 -0.4 -0.05" rpy="1.57 0.0 0.0"/>
    <axis xyz="0 0 1"/>
</joint>

<link name="left_wheel">
    <visual>
        <geometry>
             <cylinder length="0.04" radius="0.05" />
        </geometry>
        <material name="blue"/>
    </visual>
    <collision>
        <geometry>
             <cylinder length="0.04" radius="0.05" />
        </geometry>
    </collision>

    <xacro:inertial_cylinder mass="0.1" length="0.05" radius="0.05">
        <origin xyz="0 0 0" rpy="0 0 0"/>
    </xacro:inertial_cylinder>
</link>

<!-- RIGHT WHEEL -->

<joint name="right_wheel_joint" type="continuous">
    <parent link="base_link"/>
    <child link="right_wheel"/>
     <origin xyz="-0.25 0.4 -0.05" rpy="1.57 0.0 0.0"/>
    <axis xyz="0 0 -1"/>
</joint>

<link name="right_wheel">
    <visual>
        <geometry>
            <cylinder length="0.04" radius="0.05" />
        </geometry>
        <material name="blue"/>
    </visual>

    <collision>
         <geometry>
             <cylinder length="0.04" radius="0.05" />
        </geometry>

    </collision>
    <xacro:inertial_cylinder mass="0.1" length="0.05" radius="0.05">
        <origin xyz="0 0 0" rpy="0 0 0"/>
    </xacro:inertial_cylinder>
</link>



    <!-- wheel back left-->
<joint name="wheel_back_left_joint" type="continuous">

    <parent link="base_link"/>
    <child link="wheel_back_left"/>
     <origin xyz="0.25 -0.4 -0.05" rpy="1.57 0.0 0.0"/>
    <axis xyz="0 0 1"/>

</joint>
<link name="wheel_back_left">


    <visual>
        <geometry>
            <cylinder length="0.04" radius="0.05" />
        </geometry>
        <material name="blue"/>
    </visual>

    <collision>
         <geometry>
             <cylinder length="0.04" radius="0.05" />
        </geometry>

    </collision>

     <xacro:inertial_cylinder mass="0.1" length="0.05" radius="0.05">
        <origin xyz="0 0 0" rpy="0 0 0"/>
    </xacro:inertial_cylinder>
</link>



    <!-- wheel back right-->

<joint name="wheel_back_right_joint" type="continuous">

    <parent link="base_link"/>
    <child link="wheel_back_right"/>
     <origin xyz="0.25 0.4 -0.05" rpy="1.57 0.0 0.0"/>
    <axis xyz="0 0 -1"/>

</joint>

<link name="wheel_back_right">


    <visual>
        <geometry>
             <cylinder length="0.04" radius="0.05" />
        </geometry>
        <material name="blue"/>
    </visual>

    <collision>
         <geometry>
             <cylinder length="0.04" radius="0.05" />
        </geometry>

    </collision>

     <xacro:inertial_cylinder mass="0.1" length="0.05" radius="0.05">
        <origin xyz="0 0 0" rpy="0 0 0"/>
    </xacro:inertial_cylinder>
</link>





</robot>